2022-05-05 23:47:57,140 main Exception on /update_model [POST]
Traceback (most recent call last):
  File "/usr/local/lib/python3.9/site-packages/flask/app.py", line 2447, in wsgi_app
    response = self.full_dispatch_request()
  File "/usr/local/lib/python3.9/site-packages/flask/app.py", line 1952, in full_dispatch_request
    rv = self.handle_user_exception(e)
  File "/usr/local/lib/python3.9/site-packages/flask/app.py", line 1821, in handle_user_exception
    reraise(exc_type, exc_value, tb)
  File "/usr/local/lib/python3.9/site-packages/flask/_compat.py", line 39, in reraise
    raise value
  File "/usr/local/lib/python3.9/site-packages/flask/app.py", line 1950, in full_dispatch_request
    rv = self.dispatch_request()
  File "/usr/local/lib/python3.9/site-packages/flask/app.py", line 1936, in dispatch_request
    return self.view_functions[rule.endpoint](**req.view_args)
  File "/app/main.py", line 305, in update_model
    params = request.json["params"]
TypeError: 'NoneType' object is not subscriptable
2022-05-05 23:48:50,843 main Exception on /update_model [POST]
Traceback (most recent call last):
  File "/usr/local/lib/python3.9/site-packages/flask/app.py", line 2447, in wsgi_app
    response = self.full_dispatch_request()
  File "/usr/local/lib/python3.9/site-packages/flask/app.py", line 1952, in full_dispatch_request
    rv = self.handle_user_exception(e)
  File "/usr/local/lib/python3.9/site-packages/flask/app.py", line 1821, in handle_user_exception
    reraise(exc_type, exc_value, tb)
  File "/usr/local/lib/python3.9/site-packages/flask/_compat.py", line 39, in reraise
    raise value
  File "/usr/local/lib/python3.9/site-packages/flask/app.py", line 1950, in full_dispatch_request
    rv = self.dispatch_request()
  File "/usr/local/lib/python3.9/site-packages/flask/app.py", line 1936, in dispatch_request
    return self.view_functions[rule.endpoint](**req.view_args)
  File "/app/main.py", line 329, in update_model
    df_alltime = pd.read_excel("app/computed/df_alltime.xlsx")
  File "/usr/local/lib/python3.9/site-packages/pandas/util/_decorators.py", line 299, in wrapper
    return func(*args, **kwargs)
  File "/usr/local/lib/python3.9/site-packages/pandas/io/excel/_base.py", line 336, in read_excel
    io = ExcelFile(io, storage_options=storage_options, engine=engine)
  File "/usr/local/lib/python3.9/site-packages/pandas/io/excel/_base.py", line 1071, in __init__
    ext = inspect_excel_format(
  File "/usr/local/lib/python3.9/site-packages/pandas/io/excel/_base.py", line 949, in inspect_excel_format
    with get_handle(
  File "/usr/local/lib/python3.9/site-packages/pandas/io/common.py", line 651, in get_handle
    handle = open(handle, ioargs.mode)
FileNotFoundError: [Errno 2] No such file or directory: 'app/computed/df_alltime.xlsx'
